async def shutdown(dp: Dispatcher, bot: Bot):
    logging.warning("Завершение работы бота")
    await asyncio.gather(
        dp.storage.close(),
        bot.session.close(),
        return_exceptions=True  # не падает при ошибках
    )

Расскажи мне про этот код. Я асинхронность только учусь



Отлично, что изучаете асинхронность! Давайте разберём ваш код **пошагово**, объясняя каждую часть.

---

### **1. Что делает `shutdown`?**
Эта функция отвечает за **корректное завершение работы бота**:
- Закрывает хранилище (`dp.storage`) — например, если используется Redis или другая БД.
- Закрывает сессию бота (`bot.session`) — освобождает ресурсы соединения с Telegram.

---

### **2. Ключевые элементы асинхронности**

#### **`async def`**
- Функция объявлена как **асинхронная** (корутина). Это значит, что внутри неё можно использовать `await`.

#### **`await`**
- Указывает, что операция **может быть приостановлена** (например, ожидание ответа от сервера Telegram).
- В вашем коде `await` стоит перед `asyncio.gather()`, который запускает несколько асинхронных задач **параллельно**.

---

### **3. `asyncio.gather()` — запуск задач параллельно**
Вместо такого кода:
```python
await dp.storage.close()  # ждём завершения
await bot.session.close()  # только потом начинаем
```
Вы используете:
```python
await asyncio.gather(
    dp.storage.close(),
    bot.session.close(),
    return_exceptions=True
)
```
**Что это даёт?**
- Обе операции (`storage.close()` и `session.close()`) запускаются **одновременно**.
- Бот завершится быстрее, чем если бы операции выполнялись последовательно.

#### **Параметр `return_exceptions=True`**
- Если одна из задач завершится с ошибкой, `gather` не вызовет исключение, а **вернёт его как результат**.
- Без этого параметра при ошибке в `storage.close()` метод `session.close()` даже не начнётся.

**Пример:**
```python
async def task1():
    raise ValueError("Ошибка!")

async def task2():
    print("Успех")

await asyncio.gather(task1(), task2(), return_exceptions=True)
```
Выведет:
```
ValueError("Ошибка!")
Успех
```
Без `return_exceptions=True` код упадёт на первой же ошибке.

---

### **4. Что будет без `asyncio.gather`?**
Если сделать так:
```python
await dp.storage.close()  # если здесь ошибка,
await bot.session.close()  # это уже не выполнится
```
- При ошибке в `storage.close()` сессия бота **не закроется**, что может привести к утечкам ресурсов.
- `gather` с `return_exceptions=True` гарантирует, что обе операции **будут выполнены**, даже если одна упадёт.

---

### **5. Когда использовать `asyncio.gather`?**
- Когда нужно выполнить **несколько асинхронных задач** (например, HTTP-запросы, запись в БД, закрытие соединений).
- Когда задачи **не зависят друг от друга** (например, закрытие хранилища и сессии — независимые операции).

---

### **6. Альтернативы `gather`**
Если нужно контролировать задачи по отдельности:
```python
task1 = asyncio.create_task(dp.storage.close())
task2 = asyncio.create_task(bot.session.close())

await task1  # можно обработать ошибку здесь
await task2
```
Но ваш вариант с `gather` лаконичнее.

---

### **7. Ошибки, которых стоит избегать**
1. **Отсутствие `await`**  
   ```python
   asyncio.gather(...)  # без await — задачи не выполнятся!
   ```

2. **Игнорирование ошибок**  
   Даже с `return_exceptions=True` стоит проверить результат:
   ```python
   results = await asyncio.gather(
       dp.storage.close(),
       bot.session.close(),
       return_exceptions=True
   )
   for result in results:
       if isinstance(result, Exception):
           logging.error(f"Ошибка при закрытии: {result}")
   ```

---

### **Итог**
Ваш код:
- **Правильно использует асинхронность** (`async/await`, `gather`).
- **Надёжен**: не падает при ошибках в одной из задач.
- **Эффективен**: задачи выполняются параллельно.

**Совет для обучения:**  
Попробуйте написать тестовый пример с двумя асинхронными функциями (одна — падает, другая — работает) и поэкспериментируйте с `gather` с/без `return_exceptions`. Это поможет лучше понять механизм.